Workbook

Sheet KPIs
A1: Economics | B1: Data
A2: ROI | B2: =KPIs!$B$78 -> 0.17346939
A3: Total Cost | B3: =B76 -> 20384
A4: Annual Savings | B4: =sum(B72:B74) -> 23920
A5: Total Benefit | B5: =B75 -> 3536
C6: ="ROI "&TEXT(KPIs!$B$78,"0%")&" — Return per €1 invested "&TEXT(0+KPIs!$B$78,"0.00")&" €." -> ROI 17% — Return per €1 invested 0,17 €.
A7: Operatives / year | B7: Operative Data
A8: Saving Hours | B8: =B89 -> 560
A9: Number of error-free queries with AI | B9: =B87 -> 7680
A10: Queries handled with AI | B10: =B86 -> 9600
A11: Number of errors prevented by AI | B11: =B91 -> 128
A13: Adoption | B13: Adoption Data
A14: Active employees | B14: =B49 -> 80
A15: Adoption rate (%) | B15: =B41 -> 40
A16: Recurring usage (users ≥ X queries/month) | B16: =B34 -> 20
A17: Compliance incidents per year | B17: =B96 -> 192
A19: Risk and Compliance | B19: Risk Data
A20: Internal policy compliance (%) | B20: =B99 -> 98
A21: Detected bias per year | B21: =B97 -> 144
A22: Explainability level (score or %) | B22: =B98 -> 70
A23: Auditable interactions per year | B23: =B99 -> 98
A28: Input | B28: Values | C28: Description | D28: Clear concept
A29: Previous tools cost (€) | B29: 10000 | C29: Annual cost of eliminated tools | D29: Savings generated by retiring software or services that are no longer necessary due to AI implementation
A30: Current cost per error (€) | B30: 30 | C30: Cost of correcting an internal error | D30: Cost of resolving an error generated in a manual process, including employee time, operational impact, and potential delays
A31: Total employees | B31: 200 | C31: Total number of employees in the company
A32: Hourly cost (€) | B32: 18 | C32: Average labor cost per employee per hour | D32: Average hourly employee cost based on a gross annual salary of approximately €31,500 / 1,750 hours
A33: Average number of queries per month | B33: 5 | C33: Average employee time per query (minutes) | D33: Average time an employee takes to handle or resolve a query without AI assistance
A34: Number of queries per employee per month | B34: 20 | C34: Queries per employee per month | D34: Average number of queries handled by each employee per month
A36: Manual error rate per year | B36: =B34*0.1 -> 2 | C36: Query errors per employee per year | D36: Percentage of queries performed incorrectly by an employee in a year compared to the total activities executed
A37: Average hours spent on queries per month | B37: =B34*B33/60 -> 1.6666667 | C37: Average hours dedicated to query resolution | D37: Average monthly minutes spent handling queries per employee
A38: Total query time per month | B38: =B33*B34*B31/60 -> 333.33333 | C38: Total monthly hours spent on queries
A39: Query labor cost per month | B39: =B38*B32 -> 6000 | C39: Monthly query-related labor cost
A41: AI adoption rate (%) | B41: 40 | C41: Internal adoption rate (%) | D41: Percentage of employees who consistently use AI
A42: Processes handled through AI (%) | B42: 50 | C42: Actual automation rate (%) | D42: Percentage of employee processes managed by AI among those who have adopted it
A43: Error reduction rate with AI (%) | B43: 80 | C43: Percentage of errors prevented annually using AI | D43: Percentage of errors eliminated thanks to AI usage
A44: Annual AI system cost (€) | B44: 150 | C44: Annual license cost per employee
A45: AI implementation cost (€) | B45: 6000 | C45: Initial system cost | D45: Investment in the AI solution, including installation, configuration, training, and any costs associated with initial deployment
A46: AI operating cost (€) | B46: 2000 | C46: Management and maintenance cost | D46: Cost of managing the AI system, including monitoring, support, adjustments, and administration
A47: Cost per query resolved with AI (€) | B47: 0.04 | C47: Cost per query processed with AI | D47: Average cost associated with a query being handled through the AI solution
A49: Employees using AI | B49: =B31*B41% -> 80 | C49: Number of employees adopting AI
...

Sheet Formato Locker
A1: Económicos | B1: Datos | C1: Operativos / año | D1: Datos operativos | E1: Adopción | F1: Datos adopcion | G1: Riesgo y cumplimiento | H1: Datos riesgo
A2: ROI | B2: =KPIs!$B$78 -> 0.17346939 | C2: Horas ahorradas | D2: =KPIs!B89 -> 560 | E2: Empleados activos | F2: =KPIs!B49 -> 80 | G2: Cumplimiento de políticas internas (%) | H2: =KPIs!B99 -> 98
A3: Coste total | B3: =KPIs!B76 -> 20384 | C3: Nº consultas sin errores con IA | D3: =KPIs!B87 -> 7680 | E3: Tasa adopción (%) | F3: =KPIs!B41 -> 40 | G3: Bias detectado / año | H3: =KPIs!B97 -> 144
A4: Ahorro anual | B4: =SUM(KPIs!B72:B74) -> 23920 | C4: Consultas con IA | D4: =KPIs!B86 -> 9600 | E4: Uso recurrente (usuarios ≥ X consultas/mes) | F4: =KPIs!B34 -> 20 | G4: Nivel de explicabilidad (score o %) | H4: =KPIs!B98 -> 70
A5: Beneficio total | B5: =KPIs!B75 -> 3536 | C5: Nº de errores evitados con IA | D5: =KPIs!B91 -> 128 | E5: Incidentes de cumplimiento / año | F5: =KPIs!B96 -> 192 | G5: Interacciones auditables /año | H5: =KPIs!B99 -> 98
